<?xml version="1.0" encoding="utf-8"?>
<!-- This URDF was automatically created by SolidWorks to URDF Exporter! Originally created by Stephen Brawner (brawner@gmail.com) 
     Commit Version: 1.6.0-4-g7f85cfe  Build Version: 1.6.7995.38578
     For more information, please see http://wiki.ros.org/sw_urdf_exporter -->
<robot
  name="R_PX0">
  <link name="base_footprint" />
  <link
    name="base_link">
    <inertial>
      <origin
        xyz="-0.0238340891657957 7.87439868419337E-05 0.0964993270009829"
        rpy="0 0 0" />
      <mass
        value="90.3246909159885" />
      <inertia
        ixx="3.0427141358291"
        ixy="-0.00277129251253968"
        ixz="0.115541496859396"
        iyy="4.60554880003911"
        iyz="5.71138685020814E-05"
        izz="7.05947261332458" />
    </inertial>
    <visual>
      <origin
        xyz="0 0 0"
        rpy="0 0 0" />
      <geometry>
        <mesh
          filename="package://R_PX0/meshes/base_link.STL" />
      </geometry>
      <material
        name="">
        <color
          rgba="0.666666666666667 0.698039215686274 0.768627450980392 1" />
      </material>
    </visual>
    <collision>
      <origin
        xyz="0 0 0"
        rpy="0 0 0" />
      <geometry>
        <mesh
          filename="package://R_PX0/meshes/base_link.STL" />
      </geometry>
    </collision>
  </link>
  <gazebo reference="base_link">
  <material>Gazebo/Gray</material>
</gazebo>
  <link
    name="FR_LINK">
    <inertial>
      <origin
        xyz="0 0.069349 6.9389E-18"
        rpy="0 0 0" />
      <mass
        value="10.3" />
      <inertia
        ixx="0.076627"
        ixy="-8.7093E-18"
        ixz="1.2324E-18"
        iyy="0.11589"
        iyz="-2.3401E-19"
        izz="0.076627" />
    </inertial>
    <visual>
      <origin
        xyz="0 0 0"
        rpy="0 0 0" />
      <geometry>
        <mesh
          filename="package://R_PX0/meshes/FR_LINK.STL" />
      </geometry>
      <material
        name="">
        <color
          rgba="0.2 0.2 0.2 1" />
      </material>
    </visual>
    <collision>
      <origin
        xyz="0 0 0"
        rpy="0 0 0" />
      <geometry>
        <mesh
          filename="package://R_PX0/meshes/FR_LINK.STL" />
      </geometry>
    </collision>
  </link>
  <gazebo reference="FR_LINK">
  <material>Gazebo/Black</material>
</gazebo>
  <joint
    name="FR_JOINT"
    type="continuous">
    <origin
      xyz="0.2 -0.445 0.1"
      rpy="0 0 0" />
    <parent
      link="base_link" />
    <child
      link="FR_LINK" />
    <axis
      xyz="0 1 0" />
  </joint>
<gazebo reference="FR_JOINT">
  <provideFeedback>true</provideFeedback>
</gazebo>
  <link
    name="BR_LINK">
    <inertial>
      <origin
        xyz="5.5511E-17 0.069349 1.3878E-17"
        rpy="0 0 0" />
      <mass
        value="10.3" />
      <inertia
        ixx="0.076627"
        ixy="-7.0931E-18"
        ixz="-1.4477E-18"
        iyy="0.11589"
        iyz="-1.5694E-19"
        izz="0.076627" />
    </inertial>
    <visual>
      <origin
        xyz="0 0 0"
        rpy="0 0 0" />
      <geometry>
        <mesh
          filename="package://R_PX0/meshes/BR_LINK.STL" />
      </geometry>
      <material
        name="">
        <color
          rgba="0.2 0.2 0.2 1" />
      </material>
    </visual>
    <collision>
      <origin
        xyz="0 0 0"
        rpy="0 0 0" />
      <geometry>
        <mesh
          filename="package://R_PX0/meshes/BR_LINK.STL" />
      </geometry>
    </collision>
  </link>
	<gazebo reference="BR_LINK">
	  <material>Gazebo/Black</material>
	</gazebo>
  <joint
    name="BR_JOINT"
    type="continuous">
    <origin
      xyz="-0.2 -0.445 0.1"
      rpy="0 0 0" />
    <parent
      link="base_link" />
    <child
      link="BR_LINK" />
    <axis
      xyz="0 1 0" />
  </joint>
<gazebo reference="BR_JOINT">
  <provideFeedback>true</provideFeedback>
</gazebo>
  <link
    name="FL_LINK">
    <inertial>
      <origin
        xyz="0 -0.069349 -6.9389E-18"
        rpy="0 0 0" />
      <mass
        value="10.3" />
      <inertia
        ixx="0.076627"
        ixy="8.8154E-18"
        ixz="-8.1926E-19"
        iyy="0.11589"
        iyz="-4.5425E-19"
        izz="0.076627" />
    </inertial>
    <visual>
      <origin
        xyz="0 0 0"
        rpy="0 0 0" />
      <geometry>
        <mesh
          filename="package://R_PX0/meshes/FL_LINK.STL" />
      </geometry>
      <material
        name="">
        <color
          rgba="0.2 0.2 0.2 1" />
      </material>
    </visual>
    <collision>
      <origin
        xyz="0 0 0"
        rpy="0 0 0" />
      <geometry>
        <mesh
          filename="package://R_PX0/meshes/FL_LINK.STL" />
      </geometry>
    </collision>
  </link>
	<gazebo reference="FL_LINK">
	  <material>Gazebo/Black</material>
	</gazebo>
  <joint
    name="FL_JOINT"
    type="continuous">
    <origin
      xyz="0.2 0.445 0.1"
      rpy="0 0 0" />
    <parent
      link="base_link" />
    <child
      link="FL_LINK" />
    <axis
      xyz="0 -1 0" />
  </joint>
<gazebo reference="FL_JOINT">
  <provideFeedback>true</provideFeedback>
</gazebo>
  <link
    name="BL_LINK">
    <inertial>
      <origin
        xyz="5.5511E-17 -0.069349 0"
        rpy="0 0 0" />
      <mass
        value="10.3" />
      <inertia
        ixx="0.076627"
        ixy="8.7433E-18"
        ixz="-2.5659E-18"
        iyy="0.11589"
        iyz="-5.8634E-19"
        izz="0.076627" />
    </inertial>
    <visual>
      <origin
        xyz="0 0 0"
        rpy="0 0 0" />
      <geometry>
        <mesh
          filename="package://R_PX0/meshes/BL_LINK.STL" />
      </geometry>
      <material
        name="">
        <color
          rgba="0.2 0.2 0.2 1" />
      </material>
    </visual>
    <collision>
      <origin
        xyz="0 0 0"
        rpy="0 0 0" />
      <geometry>
        <mesh
          filename="package://R_PX0/meshes/BL_LINK.STL" />
      </geometry>
    </collision>
  </link>
	<gazebo reference="BL_LINK">
	  <material>Gazebo/Black</material>
	</gazebo>
  <joint
    name="BL_JOINT"
    type="continuous">
    <origin
      xyz="-0.2 0.445 0.1"
      rpy="0 0 0" />
    <parent
      link="base_link" />
    <child
      link="BL_LINK" />
    <axis
      xyz="0 -1 0" />
  </joint>
<gazebo reference="BL_JOINT">
  <provideFeedback>true</provideFeedback>
</gazebo>
  <joint name="base_joint" type="fixed">
  	<parent link="base_footprint" />
  	<child link="base_link" />
  	<origin xyz="0 0 0.05" rpy="0 0 0" />
  </joint>
  
<gazebo>
  <plugin name="skid_steer_drive_controller" filename="libgazebo_ros_skid_steer_drive.so">
    <updateRate>100.0</updateRate>
    <robotNamespace>/</robotNamespace>

    <!-- Wheel joints -->
    <leftFrontJoint>FL_JOINT</leftFrontJoint>
    <rightFrontJoint>FR_JOINT</rightFrontJoint>
    <leftRearJoint>BL_JOINT</leftRearJoint>
    <rightRearJoint>BR_JOINT</rightRearJoint>

    <!-- Wheel parameters -->
    <wheelSeparation>0.4</wheelSeparation>
    <wheelDiameter>0.215</wheelDiameter>
    <torque>50.0</torque>

    <!-- Topics and Frames -->
    <robotBaseFrame>base_footprint</robotBaseFrame>
    <odometryFrame>odom</odometryFrame>
    <commandTopic>cmd_vel</commandTopic>
    <odometryTopic>odom</odometryTopic>
    <broadcastTF>true</broadcastTF>
    <publishWheelTF>true</publishWheelTF>

  </plugin>
</gazebo>


  <transmission name="FR_trans">
    <type>transmission_interface/SimpleTransmission</type>
    <actuator name="FR_motor">
      <hardwareInterface>hardware_interface/EffortJointInterface</hardwareInterface>

    </actuator>
    <joint name="FR_JOINT">
      <hardwareInterface>hardware_interface/EffortJointInterface</hardwareInterface>

    </joint>
  </transmission>

  <transmission name="FL_trans">
    <type>transmission_interface/SimpleTransmission</type>
    <actuator name="FL_motor">
      <hardwareInterface>hardware_interface/EffortJointInterface</hardwareInterface>

    </actuator>
    <joint name="FL_JOINT">
      <hardwareInterface>hardware_interface/EffortJointInterface</hardwareInterface>

    </joint>
  </transmission>

  <transmission name="BR_trans">
    <type>transmission_interface/SimpleTransmission</type>
    <actuator name="BR_motor">
      <hardwareInterface>hardware_interface/EffortJointInterface</hardwareInterface>

    </actuator>
    <joint name="BR_JOINT">
      <hardwareInterface>hardware_interface/EffortJointInterface</hardwareInterface>

    </joint>
  </transmission>

  <transmission name="BL_trans">
    <type>transmission_interface/SimpleTransmission</type>
    <actuator name="BL_motor">
      <hardwareInterface>hardware_interface/EffortJointInterface</hardwareInterface>

    </actuator>
    <joint name="BL_JOINT">
      <hardwareInterface>hardware_interface/EffortJointInterface</hardwareInterface>

    </joint>
  </transmission>
 
<gazebo>
  <plugin name="gazebo_ros_control" filename="libgazebo_ros_control.so"/>
</gazebo>

<link name="laser_link">
  <visual>
    <origin xyz="0 0 0" rpy="0 0 0"/>
    <geometry>
      <cylinder length="0.02" radius="0.05"/>
    </geometry>
    <material name="gray">
      <color rgba="0.5 0.5 0.5 1"/>
    </material>
  </visual>
</link>
<gazebo reference="laser_link">
	<material>Gazebo/Blue</material>
</gazebo>
<joint name="laser_joint" type="fixed">
  <parent link="base_link"/>
  <child link="laser_link"/>
  <origin xyz="0 0 0.25" rpy="0 0 0"/>
</joint>
<gazebo reference="laser_link">
  <sensor type="ray" name="laser_sensor">
    <pose>0 0 0 0 0 0</pose>
    <visualize>true</visualize>
    <update_rate>20.0</update_rate>
    <ray>
      <scan>
        <horizontal>
          <samples>720</samples>
          <resolution>1</resolution>
          <min_angle>-3.14159</min_angle>
          <max_angle>3.14159</max_angle>
        </horizontal>
      </scan>
      <range>
        <min>0.1</min>
        <max>10.0</max>
        <resolution>0.01</resolution>
      </range>
    </ray>
    <plugin name="gazebo_ros_laser" filename="libgazebo_ros_laser.so">
      <topicName>scan</topicName>
      <frameName>laser_link</frameName>
    </plugin>
  </sensor>
</gazebo>

</robot>
